[ 2025-06-18 17:36:36,019 ] 16 root - INFO - Data ingestion started
[ 2025-06-18 17:36:36,019 ] 53 root - INFO - Entered initiate_data_ingestion method of Data_Ingestion class
[ 2025-06-18 17:36:37,155 ] 58 root - INFO - Got the data from mongodb
[ 2025-06-18 17:36:37,156 ] 63 root - INFO - Exporting collection to Artifacts/06_18_2025_17_36_35/data_ingestion/feature_store
[ 2025-06-18 17:36:37,190 ] 68 root - INFO - Exported collection data as csv file
[ 2025-06-18 17:36:37,190 ] 76 root - INFO - Exporting train dataset to file: [Artifacts/06_18_2025_17_36_35/data_ingestion/ingested/train.csv]
[ 2025-06-18 17:36:37,215 ] 78 root - INFO - Exporting test dataset to file: [Artifacts/06_18_2025_17_36_35/data_ingestion/ingested/test.csv]
[ 2025-06-18 17:36:37,222 ] 80 root - INFO - Exported train and test dataset
[ 2025-06-18 17:36:37,222 ] 86 root - INFO - Data ingestion artifact: DataIngestionArtifact(trained_file_path='Artifacts/06_18_2025_17_36_35/data_ingestion/ingested/train.csv', test_file_path='Artifacts/06_18_2025_17_36_35/data_ingestion/ingested/test.csv')
[ 2025-06-18 17:36:37,222 ] 18 root - INFO - Data ingestion completed
[ 2025-06-18 17:36:37,222 ] 29 root - ERROR - Error occured in python script name [/Users/abhisheksuresh/Documents/networksecurity/networksecurity/components/data_validation.py] line number [17] error message ['DataValidation' object has no attribute 'read_yaml_file']
Traceback (most recent call last):
  File "/Users/abhisheksuresh/Documents/networksecurity/networksecurity/components/data_validation.py", line 17, in __init__
    self.schema_config=self.read_yaml_file(SCHEMA_FILE_PATH)
AttributeError: 'DataValidation' object has no attribute 'read_yaml_file'

During handling of the above exception, another exception occurred:

Traceback (most recent call last):
  File "/Users/abhisheksuresh/Documents/networksecurity/main.py", line 22, in <module>
    data_validation=DataValidation(data_validation_config=data_validation_config,data_ingestion_artifact=data_ingestion_artifact)
  File "/Users/abhisheksuresh/Documents/networksecurity/networksecurity/components/data_validation.py", line 19, in __init__
    raise NetworkSecurityException(e,sys)
networksecurity.exception.exception.NetworkSecurityException: Error occured in python script name [/Users/abhisheksuresh/Documents/networksecurity/networksecurity/components/data_validation.py] line number [17] error message ['DataValidation' object has no attribute 'read_yaml_file']
