[ 2025-06-18 17:39:29,152 ] 16 root - INFO - Data ingestion started
[ 2025-06-18 17:39:29,152 ] 53 root - INFO - Entered initiate_data_ingestion method of Data_Ingestion class
[ 2025-06-18 17:39:30,160 ] 58 root - INFO - Got the data from mongodb
[ 2025-06-18 17:39:30,160 ] 63 root - INFO - Exporting collection to Artifacts/06_18_2025_17_39_28/data_ingestion/feature_store
[ 2025-06-18 17:39:30,191 ] 68 root - INFO - Exported collection data as csv file
[ 2025-06-18 17:39:30,191 ] 76 root - INFO - Exporting train dataset to file: [Artifacts/06_18_2025_17_39_28/data_ingestion/ingested/train.csv]
[ 2025-06-18 17:39:30,214 ] 78 root - INFO - Exporting test dataset to file: [Artifacts/06_18_2025_17_39_28/data_ingestion/ingested/test.csv]
[ 2025-06-18 17:39:30,220 ] 80 root - INFO - Exported train and test dataset
[ 2025-06-18 17:39:30,220 ] 86 root - INFO - Data ingestion artifact: DataIngestionArtifact(trained_file_path='Artifacts/06_18_2025_17_39_28/data_ingestion/ingested/train.csv', test_file_path='Artifacts/06_18_2025_17_39_28/data_ingestion/ingested/test.csv')
[ 2025-06-18 17:39:30,220 ] 18 root - INFO - Data ingestion completed
[ 2025-06-18 17:39:30,222 ] 29 root - ERROR - Error occured in python script name [/Users/abhisheksuresh/Documents/networksecurity/networksecurity/components/data_validation.py] line number [16] error message [Error occured in python script name [/Users/abhisheksuresh/Documents/networksecurity/networksecurity/utils/main_utils/utils.py] line number [14] error message [while scanning a simple key
  in "networksecurity/data_schema/schema.yaml", line 37, column 1
could not find expected ':'
  in "networksecurity/data_schema/schema.yaml", line 38, column 1]]
Traceback (most recent call last):
  File "/Users/abhisheksuresh/Documents/networksecurity/networksecurity/utils/main_utils/utils.py", line 14, in read_yaml_file
    return yaml.safe_load(yaml_file)
  File "/Users/abhisheksuresh/Documents/networksecurity/.venv/lib/python3.10/site-packages/yaml/__init__.py", line 125, in safe_load
    return load(stream, SafeLoader)
  File "/Users/abhisheksuresh/Documents/networksecurity/.venv/lib/python3.10/site-packages/yaml/__init__.py", line 81, in load
    return loader.get_single_data()
  File "/Users/abhisheksuresh/Documents/networksecurity/.venv/lib/python3.10/site-packages/yaml/constructor.py", line 49, in get_single_data
    node = self.get_single_node()
  File "/Users/abhisheksuresh/Documents/networksecurity/.venv/lib/python3.10/site-packages/yaml/composer.py", line 36, in get_single_node
    document = self.compose_document()
  File "/Users/abhisheksuresh/Documents/networksecurity/.venv/lib/python3.10/site-packages/yaml/composer.py", line 55, in compose_document
    node = self.compose_node(None, None)
  File "/Users/abhisheksuresh/Documents/networksecurity/.venv/lib/python3.10/site-packages/yaml/composer.py", line 84, in compose_node
    node = self.compose_mapping_node(anchor)
  File "/Users/abhisheksuresh/Documents/networksecurity/.venv/lib/python3.10/site-packages/yaml/composer.py", line 133, in compose_mapping_node
    item_value = self.compose_node(node, item_key)
  File "/Users/abhisheksuresh/Documents/networksecurity/.venv/lib/python3.10/site-packages/yaml/composer.py", line 64, in compose_node
    if self.check_event(AliasEvent):
  File "/Users/abhisheksuresh/Documents/networksecurity/.venv/lib/python3.10/site-packages/yaml/parser.py", line 98, in check_event
    self.current_event = self.state()
  File "/Users/abhisheksuresh/Documents/networksecurity/.venv/lib/python3.10/site-packages/yaml/parser.py", line 449, in parse_block_mapping_value
    if not self.check_token(KeyToken, ValueToken, BlockEndToken):
  File "/Users/abhisheksuresh/Documents/networksecurity/.venv/lib/python3.10/site-packages/yaml/scanner.py", line 115, in check_token
    while self.need_more_tokens():
  File "/Users/abhisheksuresh/Documents/networksecurity/.venv/lib/python3.10/site-packages/yaml/scanner.py", line 152, in need_more_tokens
    self.stale_possible_simple_keys()
  File "/Users/abhisheksuresh/Documents/networksecurity/.venv/lib/python3.10/site-packages/yaml/scanner.py", line 291, in stale_possible_simple_keys
    raise ScannerError("while scanning a simple key", key.mark,
yaml.scanner.ScannerError: while scanning a simple key
  in "networksecurity/data_schema/schema.yaml", line 37, column 1
could not find expected ':'
  in "networksecurity/data_schema/schema.yaml", line 38, column 1

During handling of the above exception, another exception occurred:

Traceback (most recent call last):
  File "/Users/abhisheksuresh/Documents/networksecurity/networksecurity/components/data_validation.py", line 16, in __init__
    self.schema_config=read_yaml_file(SCHEMA_FILE_PATH)
  File "/Users/abhisheksuresh/Documents/networksecurity/networksecurity/utils/main_utils/utils.py", line 16, in read_yaml_file
    raise NetworkSecurityException(e,sys)
networksecurity.exception.exception.NetworkSecurityException: Error occured in python script name [/Users/abhisheksuresh/Documents/networksecurity/networksecurity/utils/main_utils/utils.py] line number [14] error message [while scanning a simple key
  in "networksecurity/data_schema/schema.yaml", line 37, column 1
could not find expected ':'
  in "networksecurity/data_schema/schema.yaml", line 38, column 1]

During handling of the above exception, another exception occurred:

Traceback (most recent call last):
  File "/Users/abhisheksuresh/Documents/networksecurity/main.py", line 22, in <module>
    data_validation=DataValidation(data_validation_config=data_validation_config,data_ingestion_artifact=data_ingestion_artifact)
  File "/Users/abhisheksuresh/Documents/networksecurity/networksecurity/components/data_validation.py", line 18, in __init__
    raise NetworkSecurityException(e,sys)
networksecurity.exception.exception.NetworkSecurityException: Error occured in python script name [/Users/abhisheksuresh/Documents/networksecurity/networksecurity/components/data_validation.py] line number [16] error message [Error occured in python script name [/Users/abhisheksuresh/Documents/networksecurity/networksecurity/utils/main_utils/utils.py] line number [14] error message [while scanning a simple key
  in "networksecurity/data_schema/schema.yaml", line 37, column 1
could not find expected ':'
  in "networksecurity/data_schema/schema.yaml", line 38, column 1]]
